Workbook

Sheet Claude Log
A1: Turn # | B1: Date | C1: User Request | D1: Action Taken | E1: Details | F1: Outcome
A2: 1 | B2: 46227 | C2: Asked me to review the whole workbook and explain what it is. | D2: Read both sheets (Traditional + EduWand) and summarised the model's purpose and structure. | E2: Identified it as a time-savings/value-prop model for EduWand AI EdTech across Teacher/Student/Parent/Admin personas; noted hardcoded (non-linked) values, no assumptions block, no source citations, formatting not yet to standards. | F2: Explanation delivered in chat; flagged golden-rule violations and offered to restructure into a linked, sourced, colour-coded model.
A3: 2 | B3: 46227 | C3: Clarified PRD scope (tablets only, local AI = next year); asked whether ERP integration is technically feasible to smooth adoption; wants it broken into workflows, per-module risks, professional-skill research, and reviewed a PRD guide link. | D3: Researched ERP integration feasibility (global OneRoster/Ed-Fi standards + Indian ERP market) and reviewed provided PRD guide; broke ERP integration into 9 workflows; proposed connector-framework approach and reshaped PRD structure. | E3: Findings: Indian ERP market fragmented/proprietary (Entab closed/partnership-gated, Fedena & OpenEduCat have REST APIs); no OneRoster/Ed-Fi adoption in India; recommend CSV-first connector framework + APIs where available + partnerships for incumbents. Added ERP Integration section + per-module Risks blocks; tablets-only, local AI to roadmap. | F3: Awaiting user approval to build. Two open questions: (1) which incumbent ERP pilot schools run, (2) system-of-record for attendance/marks (one-way vs two-way sync).
A4: 3 | B4: 46227 | C4: Founder confirmed rip-and-replace intent (schools stop using old ERP; data on Google Cloud); approved CSV-first (no API); asked how long to shift a 1,000-student school off an existing ERP; asked me to confirm his (non-technical) understanding. | D4: Researched school/ERP migration timelines; confirmed founder's mental model (one-time CSV import, not live sync); reframed PRD integration approach and produced a pitch-ready answer. | E4: Benchmarks: SMB ERP go-live 6-12 wks; education SIS live 8-16 wks (driven by source-data quality); migration phase 4-8 wks; cleansing/mapping = 50-70% of effort; poor data quality #1 failure cause. Estimate for 1,000-student school via CSV: ~4-6 wks to go live (mostly cleanup+training, not import). Distinguished go-live vs full adoption (~10mo ramp already in model). PRD change: replace live-sync ERP framework with one-time 'Data Migration & Onboarding' CSV engine + in-app data-quality checker; no API in V1. | F4: Founder's understanding confirmed correct. Awaiting explicit go-ahead to build the PRD tab (approach now simplified). Then build section-by-section per formatting rules.
A5: 4 | B5: 46227 | C5: Approved the PRD build; asked me to build it out thoroughly. | D5: Built a complete, colour-coded, sourced PRD as a new 'PRD' tab (15 sections, rows 2-218). | E5: Sections: Doc Control, Vision+Key Figures (blue sourced inputs), Problem Statement, Goals/Non-Goals, Personas, Success Metrics (North-Star/leading/gate), Product Scope (AI, Smart ERP, Socratic Tutor, Digital Library, Hardware — each with features/user stories/FRs/acceptance/risks), Data Migration & Onboarding (one-time CSV, 9 objects, ~4-6wk timeline), User Journey, NFRs (DPDP call-out), Data & Analytics, Pricing & Entitlement (prices linked green to Key Figures), Roadmap, Assumptions/Dependencies/Open Questions (straight-line=pink, open Qs highlighted), Sources. Golden rules applied: A1 spacer, content from B2, ₹ 1-decimal, no gridlines, colour code, source notes. | F5: Verified: 15 sections, 0 formula errors, gridlines off, linked prices resolve (=C31..C35). Awaiting founder review; can hand to PowerPoint/Word for a doc version; open question #1 (which incumbent ERP) still needed.
A6: 5 | B6: 46227 | C6: Repositioned Enquiry-Capture/Enrolment-Growth as the flagship to build first; remove ALL pricing/margins; reframe PRD so Fovia can estimate build time & cost; recheck. (Full rebuild was declined, so edits done in place.) | D6: Edited PRD in place: added flagship module, added a Build Scope guide, scrubbed pricing, reframed purpose, renumbered. | E6: Added 7.1 ★ Enrolment Growth Engine (Priority-1, detailed FRs: omni-channel capture, admissions pipeline, automated SMS/WhatsApp/email follow-up, analytics); renumbered modules 7.2-7.6; new Section 8 'Build Scope & Effort Guide' (component × priority × complexity × effort drivers + ask Fovia for workplan). Scrubbed pricing: Key Figures 40L saving -> institution size range; Digital Library ₹400 removed; Hardware financials removed; 'Module attach rate' metric -> Lesson Studio usage + enquiry conversion metric. Reframed purpose (build time/cost) in subtitle + exec summary; renumbered sections 9-12; MVP scope & journey Stage 1 now lead with flagship; fixed Sources intro. | F6: Verified: 15 sections contiguous, 0 formula errors, no pricing/margins left. Flagged unrecognised 'promotional usage credits for fable' request as out-of-context; awaiting founder review.
A7: 7 | B7: 46228 | C7: Shared 8 blocks of CTO review comments on the PRD and asked me to go through and discuss them (no edits requested yet). | D7: Read the full PRD tab and the EduWand time-saving tab, then gave a point-by-point verdict on all 8 comments: agreed/disagreed, added what the CTO missed, and proposed a fix list ranked by blocking severity. | E7: Key findings: (a) CTO is right on the flagship-vs-migration contradiction — recommended land-and-expand and rewording the 'no parallel running' non-goal plus FR-EG-6; (b) Sep-2026 MVP not survivable — recommended removing the date from the vendor doc and letting Fovia propose it; added missing DLT/TRAI SMS registration + WhatsApp BSP + gateway KYC as external gates; (c) North Star DEFENDED with numbers — model saves 72.8 hrs total, less 19.2 hrs Teaching and 2.0 hrs Doubt Solving = 51.6 hrs of genuine admin time reclaimed, so >50 survives; found a real modelling bug the CTO missed (EduWand+Infra column drives Teaching from 96 hrs to 0); (d) agreed on retention-policy contradiction and flagged DPDP s.9 behavioural-profiling-of-minors risk against FR-AI-2 as needing named legal owner; (e) agreed all missing scenarios, ranked year-end rollover, offline fee reconciliation and multi-school-trust tenancy as the three non-retrofittable ones; (f) agreed Socratic Tutor safeguarding gap, added POCSO s.19 mandatory reporting and the nuance that disclosures must NOT auto-route to parents; (g) agreed on Fovia estimate gaps, quantified scale (100k students, 200k parents, ~4k teachers, attendance spike in a 15-min window) and flagged IP ownership as existential; (h) agreed all hygiene fixes — 46227 = 24 Jul 2026, 46266 = 1 Sep 2026, Open Q1 (which incumbent ERP) confirmed still unanswered in this log. | F7: Discussion delivered in chat; no PRD cells changed yet. Awaiting founder decision on land-and-expand vs full-replace, and on the MVP date, before applying edits. Hygiene fixes (dates, 38.8%, typos, Open Q numbering) can be done immediately on approval.
A8: 8 | B8: 46228 | C8: Reviewed CTO's 8 comments on the PRD, then gave three decisions: adopt land-and-expand, remove the MVP date, and hold teaching hours at 96 (savings are administrative only). Asked to apply the resulting fixes. | D8: Applied a full remediation pass across the PRD tab and the EduWand time-saving model. Fixed the model, rewrote the commercial model as land-and-expand, stripped the MVP date, added two new PRD sections (7.7 School Operations, 8A External Dependencies & Lead Times), a per-object data retention policy, a child-safeguarding protocol, concrete scale/concurrency figures, delivery/QA/IP terms, and a rebuilt Open Questions list. | E8: MODEL: EduWand!G11 and K11 set to 0 so Teaching holds at 96 hrs. Found and fixed a separate bug — L3:L15 used =H*K instead of =H*(1-K), which made the 'with infra' scenario look SLOWER than software-only on 12 of 13 rows. Added I22/L22 (time saved) and I23/L23 (admin-only, highlighted). I21/L21 now show positive percentages. PRD: C22 and C23 now link green to EduWand!I23 and I21 rather than repeating hardcodes. North-Star restated as administrative time with a time-diary measurement method (T0 / T+3 / T+6) replacing in-app time tracking. Land-and-expand written into C18, C38, C66, C69 (new FR-EG-11 CSV export, FR-EG-12 standalone operability), C129 and C194. MVP date removed from C185, B183, C138, C139. New 7.7 rows 113-124 covers year rollover, TC, offline fee reconciliation, guardian-to-many-children linkage, multi-school trusts, regional language, timetable substitution, data exit (FR-OPS-1 to 13). New 8A rows 141-150 covers WhatsApp API, DLT/TRAI (was entirely missing), AI provider, payment gateway, DPDP opinion, GCP, content/tablets. Retention schedule and Delivery/QA/IP at rows 204-205. Safeguarding FR-ST-7 to FR-ST-14 added to 7.4. DPDP s.9 child-profiling risk added to 7.2 with a teacher-initiated fallback design. Open Questions rebuilt as 1-10 with question 1 (incumbent ERP) restored. Typos fixed: 'Covereby'->'Covered by', 'Ai Module'. Dates C8 and Claude Log column B formatted. Gridlines turned off on Claude Log. | F8: PRD tab now B2:H237 (was B2:H211). Verified: zero formula errors across all four sheets; C22 shows 51.6 hrs and C23 shows 28.6%; model shows 187 -> 134 hrs. OPEN: the headline moves from 38.8% to 28.6% / 51.6 admin hrs, so the pitch deck (slide 4) and the financial model still carry the old figure and need updating — flagged to user, not yet pushed. Open Questions 1, 3, 5, 7, 8, 9, 10 still need owners and dates before the PRD goes to Fovia.

Sheet PRD
B2: EduWand Platform — Product Requirements Document (PRD)
B3: An AI-native ecosystem for real classroom workflows · Product of LessonForge · Prepared for Fovia Infotech to scope build effort, timeline & cost
B5: 1. DOCUMENT CONTROL
B6: Document | C6: EduWand Platform — Product Requirements Document (PRD)
B7: Version | C7: V1
B8: Date | C8: 46229
B9: Product | C9: EduWand — an AI-native ecosystem for real classroom workflows (a product of LessonForge). Mobile + Web (iOS & Android).
B10: Document owner | C10: Melvyn Brodie — Founder & CEO, LessonForge
B11: Prepared for | C11: Fovia Infotech — external technology build partner (the team building the application)
B12: Contributors | C12: Aneesh Reddy Edunuru — Co-Founder & CTO
B13: Status | C13: Reviewed
B14: Confidentiality | C14: Confidential — for LessonForge and Fovia Infotech only. Covered by NDA.
B16: 2. PRODUCT VISION & EXECUTIVE SUMMARY
B17: Vision | C17: Give schools their time back and personalise education at scale — by integrating AI in teacher's workflows and automating the administrative workflows that consume roughly half of a teacher's day, so educators can focus on the job they were hired for: teaching.
B18: Executive summary | C18: EduWand is an AI-native software ecosystem for edcational institutions in India, built around real classroom workflows. Its flagship — built and sold first — is the Enrolment Growth Engine: it captures every prospective-student enquiry and automates admissions follow-up to grow enrolment year on year. Around it sit supporting modules — Smart ERP, an AI Module, a Socratic AI Tutor and a Digital Content Library — plus an optional teacher-tablet layer. COMMERCIAL MODEL — LAND AND EXPAND. Schools already run a basic ERP, so EduWand does not ask them to rip it out on day one. The Enrolment Growth Engine is sold and deployed STANDALONE, running alongside the school's existing ERP: it owns enquiries and admissions only, and hands admitted students back to the incumbent ERP by CSV export. This is the LAND phase, and it deliberately involves a period of parallel running, scoped to admissions. The full platform — Smart ERP as system of record, with one-time CSV migration and switch-off of the old ERP — is the EXPAND phase, sold as a second decision once the school has seen the enrolment result. Section 9 (Data Migration & Onboarding) describes the EXPAND phase only; it does not apply to a standalone flagship deployment. It is delivered as mobile and web apps (iOS & Android) (compatible with tablets), is DPDP-compliant, and runs on Google Cloud. The purpose of this PRD is to give Fovia Infotech enough detail to scope the build — development effort, timeline and cost. It deliberately excludes commercial pricing and margins.
B20: KEY FIGURES AT A GLANCE (blue = hardcoded input / assumption; hover a value for its source)
B21: Metric | C21: Value | D21: Source
B22: Teacher admin time reclaimed (hrs / teacher / month) | C22: =EduWand!I23 -> 51.586389 | D22: Time-Saving analysis (this workbook) — EduWand tab, row 23 (linked)
B23: Share of total teacher workload reclaimed (%) | C23: =EduWand!I21 -> 0.28591606 | D23: Time-Saving analysis (this workbook) — EduWand tab, row 21 (linked)
B24: Institutions supported (size range) | C24: 500 – 3,500 | D24: Founder direction / platform scope
B25: Target go-live — 1,000-student school (weeks) | C25: 4 – 6 | D25: Analyst estimate — SIS migration benchmarks (see Section 8 & 15)
B27: 3. PROBLEM STATEMENT
B28: Education starts with a conversation but gets buried under administrative work. EduWand targets five connected problems across the four stakeholders. Evidence is drawn from the Time-Saving analysis (this workbook) and the EduWand pitch deck.
B29: Stakeholder | C29: Problem today | G29: Evidence & source
B30: Teacher | C30: Roughly half of a teacher's day goes to administrative workflows — attendance, lesson planning, notebook correction, parent communication, reports — instead of teaching. | G30: Time-Saving analysis: teacher baseline ~187 hrs/month. Pitch v2 — slide 2 (2/19).
B31: Student | C31: Students use AI to shortcut thinking (answers without effort), numbing the habit of learning; and they receive one-size-fits-all instruction with no personalisation. | G31: Pitch v2 — slide 2 (2/19); Time-Saving analysis (Student block).
B32: Parent | C32: Parents feel disconnected — updates arrive on unorganised WhatsApp groups and they are barely aware of what happens in class. | G32: Pitch v2 — slide 2 (2/19); Time-Saving analysis (Parent block).
B33: School / Admin | C33: Leadership decides on historical, fragmented data; leads and the student lifecycle are tracked manually (slowing admissions); staff use personal devices, exposing the school to data-security and reputational risk. | G33: Time-Saving analysis: admin baseline ~179 hrs/month. Pitch v2 — slides 2 & 5.
B34: System-level | C34: No data is systematically captured, tracked or processed across the institution, so nothing compounds into insight or personalisation. | G34: Pitch v2 — slide 2 (2/19).
B36: 4. GOALS & NON-GOALS
B37: Goals | C37: • Reclaim teacher ADMINISTRATIVE time — automate non-teaching workflows so teachers spend materially less time on admin (North-Star: >50 hrs of admin time reclaimed / teacher / month; model shows 51.6). Teaching hours are deliberately unchanged — EduWand improves how a class is planned and delivered, it does not reduce time in front of students. • Personalise learning — let teachers create and grade personalised assignments; give students a Socratic AI tutor that guides thinking rather than handing over answers. • One shared context — a single system of record (on Google Cloud) across School, Teacher, Student and Parent, with no duplicate data entry. • Live visibility — real-time dashboards for leadership and automated daily updates for parents. • Easy switching — migrate an institution's existing data via a one-time CSV load so a ~1,000-student school goes live in ~4–6 weeks. • Compliance by design — DPDP-compliant handling of student data; content aligned to CBSE / ICSE / State boards. • AI-native delivery — mobile + web apps (iOS & Android), built with AI at the core.
B38: Non-Goals (V1) | C38: • No live, ongoing two-way sync with incumbent ERPs — EduWand never maintains a permanent real-time integration. In the LAND phase the flagship coexists with the old ERP and exchanges data by CSV export only; in the EXPAND phase EduWand replaces the old system via a one-time CSV migration. • No on-device / local AI in V1 — planned for Year 2 (roadmap). • No student-issued hardware in V1 — teacher tablets only; student hardware is not yet planned. • No biometric hardware in V1 — deferred. • Not a direct-to-consumer (B2C) product — EduWand is sold to institutions (B2B). • We do not author CPD or library content ourselves — it is partner-sourced; and we connect to payment gateways rather than building one. • We do NOT claim zero parallel running. A school that buys the flagship alone runs EduWand for admissions and its existing ERP for everything else, by design, until it chooses to expand.
B40: 5. PERSONAS
B41: Persona | C41: Goals | E41: Pains today | G41: What EduWand gives them
B42: School Leadership / Administrator | C42: Grow enrolment; run efficient operations; ensure quality & compliance; make informed decisions. | E42: Decisions on stale, fragmented data; manual lead & lifecycle tracking; vendor & staffing overload (~179 hrs/mo). | G42: Live analytics dashboard; digital student lifecycle (enquiry → admission → reports); vendor & staffing tools; central notices.
B43: Teacher | C43: Teach well; plan & grade fast; keep parents informed; track each student's progress. | E43: ~50% of the day on admin (attendance, planning, notebook correction, parent comms); working off personal devices. | G43: Lesson Studio (create material); Assignment Lab (personalised create + grade); digital attendance; one-tap parent updates; dedicated tablet.
B44: Student | C44: Learn effectively; get help when stuck; complete assignments; use AI the right way. | E44: AI shortcuts that numb thinking; one-size-fits-all instruction; slow doubt resolution. | G44: Socratic AI tutor (guides, does not hand over answers); personalised assignments; escalate to the teacher when still stuck.
B45: Parent | C45: Stay informed about their child; communicate with the teacher; support learning at home. | E45: Disconnected; unorganised WhatsApp updates; little visibility into what happens in class. | G45: Parent login with a live classroom view; automated daily updates & reminders; direct chat with the teacher.
B47: 6. SUCCESS METRICS
B48: Metrics are layered so everyone knows what 'working' means and who can move each one. The North-Star is the core outcome (teacher time reclaimed). Leading indicators are what the build partner can directly instrument and influence. Acceptance gates are thresholds the pilot must clear before wider rollout. Commercial metrics (ARR, attach, churn) are tracked in the financial model and only referenced here. Targets shown in blue are assumptions you can change.
...

Sheet Traditional
B1: NO TIME FOR PERSONAL AND PROFESSIONAL DEVELOPMENT | I1: No Monitored Usage of AI
B2: Teacher | C2: Workflow | D2: Time Taken | E2: Frequency Per Month | F2: Time Taken in a month | G2: Time Taken in a year | I2: Student | J2: Workflow | K2: Time Taken | L2: Frequency Per Month | M2: Time Taken in a month | N2: Time Taken in a year
A3: 1 | B3: Attendance | C3: Daily attendance at the start of the day, recording in registers/ERP system | D3: 15 | E3: 24 | F3: =E3*D3/60 -> 6 | G3: =F3*12 -> 72 | H3: 1 | I3: Time Spent on AI for education | J3: Usage of AI in doing their homework without guardrails, numbing them to think | K3: 60 | L3: 24 | M3: =L3*K3/60 -> 24 | N3: =M3*12 -> 288
A4: =A3+1 -> 2 | B4: Lesson Planning | C4: Each class needs to be planned and teachers keep records or what was done, and what are next classes aimed for and how they can deliver the same (eg: CBSE Mandated 5E lesson plans to be recorded by teachers for documentation) | D4: =15 -> 15 | E4: =2*24 -> 48 | F4: =D4*E4/60 -> 12 | G4: =F4*12 -> 144 | H4: =H3+1 -> 2 | I4: Time Spent in classroom | J4: Daily classes | K4: =45*6 -> 270 | L4: 24 | M4: =L4*K4/60 -> 108 | N4: =M4*12 -> 1296
A5: =A4+1 -> 3 | B5: Question Bank | C5: Currently only happens for quarter end exams, sources include external guides, competitive exam books, school purchased Books (all static material, nothing adjusting to the need and understanding of a kid) | D5: =3*60 -> 180 | E5: =1/3 -> 0.33333333 | F5: =D5*E5/60 -> 1 | G5: =F5*12 -> 12 | H5: =H4+1 -> 3 | I5: Homework (if any:P) | J5: Homework from daily lectures | K5: 30 | L5: 24 | M5: =L5*K5/60 -> 12 | N5: =M5*12 -> 144
A6: =A5+1 -> 4 | B6: Content Research | C6: This would include the teacher trying to find online material from youtube, google to explain the same topics in the books available | D6: 5 | E6: 8 | F6: =ROUND(E6*D6/60,2) -> 0.67 | G6: =F6*12 -> 8.04 | H6: =H5+1 -> 4 | I6: Co-curricular activities (Projects,competitions etc) | K6: 30 | L6: 24 | M6: =L6*K6/60 -> 12 | N6: =M6*12 -> 144
A7: =A6+1 -> 5 | B7: Doubt Solving | C7: Happens immedietly whena students gets a chance to talk to the teacher, if this happens often after a class, takes up an entire lecture. | D7: 45 | E7: 3 | F7: =E7*D7/60 -> 2.25 | G7: =F7*12 -> 27 | H7: =H6+1 -> 5
A8: =A7+1 -> 6 | B8: Parent Communication | C8: In some schools parents are updated on a daily basis of what was done in class through Whatsapp. Rarely any school has a central app for communication. A teacher with a class of 25 students has to deal with 25 set of parents at a time, with updates on groups and responding to individual doubts. | D8: 30 | E8: 24 | F8: =E8*D8/60 -> 12 | G8: =F8*12 -> 144 | H8: =H7+1 -> 6
A9: =A8+1 -> 7 | B9: Notebook Correction (Homework) | C9: Teachers get their students to do daily assignments in notebooks (K-12), which if the teacher has time, carries it back and forth from classrom to home to staff room to classroom, exposing risks to injury. | D9: =8*60 -> 480 | E9: 2 | F9: =E9*D9/60 -> 16 | G9: =F9*12 -> 192 | H9: =H8+1 -> 7
A10: =A9+1 -> 8 | B10: LMS Update | C10: Any Learning material the teacher used in class is updated on an LMS Portal (which is never looked back on) | D10: 10 | E10: 24 | F10: =D10*E10/60 -> 4 | G10: =F10*12 -> 48 | H10: =H9+1 -> 8
A11: =A10+1 -> 9 | B11: Teaching | C11: A K12 Teacher has 3-4 lectures per day | D11: =60*4 -> 240 | E11: 24 | F11: =E11*D11/60 -> 96 | G11: =F11*12 -> 1152 | H11: =H10+1 -> 9
A12: =A11+1 -> 10 | B12: Assembly | C12: Every school holds an assembly everyday. Planning involves - news runs, thought of the day, pledge, notice announcments, awards, birthdays. | D12: 30 | E12: 2 | F12: =E12*D12/60 -> 1 | G12: =F12*12 -> 12 | H12: =H11+1 -> 10
A13: =A12+1 -> 11 | B13: Report Building | C13: Ad hoc reports of students/class/incedent for internal meetings | D13: 30 | E13: 5 | F13: =E13*D13/60 -> 2.5 | G13: =F13*12 -> 30 | H13: =H12+1 -> 11
A14: =A13+1 -> 12 | B14: Co Corricular Activities | C14: Planning and conducting events/activities/picnics etc to keep students engaged | D14: 120 | E14: 2 | F14: =E14*D14/60 -> 4 | G14: =F14*12 -> 48 | H14: =H13+1 -> 12
A15: =A14+1 -> 13 | B15: School Events | C15: Annual Event Planning - Assumption includes the amount spent on practice in that one month of prepping towards the events | D15: 120 | E15: 15 | F15: =E15*D15/60 -> 30 | G15: =F15*12 -> 360 | H15: =H14+1 -> 13
A16: =A15+1 -> 14 | H16: =H15+1 -> 14
A17: =A16+1 -> 15 | H17: =H16+1 -> 15
B18: Total | F18: =ROUND(SUM(F3:F17),0) -> 187 | I18: Total | M18: =ROUND(SUM(M3:M17),0) -> 156
B19: Weekly Average | F19: =ROUND(F18/4,0) -> 47 | I19: Weekly Average | M19: =ROUND(M18/4,0) -> 39
B20: Daily Average | F20: =ROUND(F19/6,0) -> 8 | I20: Daily Average | M20: =ROUND(M19/6,0) -> 7
B25: Huge Gap in what parents know about what is happening in class | I25: No Live Data to take precautions
B26: Parent | C26: Workflow | D26: Time Taken | E26: Frequency Per Month | F26: Time Taken in a month | G26: Time Taken in a year | I26: Administrator | J26: Workflow | K26: Time Taken | L26: Frequency Per Month | M26: Time Taken in a month | N26: Time Taken in a year
A27: 1 | B27: Teacher Interaction | C27: Check ins with teacher, getting updates on their child etc | D27: 30 | E27: 5 | F27: =E27*D27/60 -> 2.5 | G27: =F27*12 -> 30 | H27: 1 | I27: Vendor Management | J27: Approving bills, co ordinating contracts, Budgeting and Buying | K27: 120 | L27: 24 | M27: =L27*K27/60 -> 48 | N27: =M27*12 -> 576
A28: =A27+1 -> 2 | B28: Child Interaction | C28: Sit with their children to help them with homework | D28: 30 | E28: 5 | F28: =E28*D28/60 -> 2.5 | G28: =F28*12 -> 30 | H28: =H27+1 -> 2 | I28: School Organization and Staffing | J28: Staffing teachers and managing their schedule, Leadership and Culture, Programming and building systems, Hiring and training | K28: 180 | L28: 20 | M28: =L28*K28/60 -> 60 | N28: =M28*12 -> 720
A29: =A28+1 -> 3 | B29: Administrative activities | C29: Admissions, PTM, Payments | D29: =8*60 -> 480 | E29: =1/12 -> 0.083333333 | F29: =ROUND(E29*D29/60,2) -> 0.67 | G29: =ROUND(F29*12,0) -> 8 | H29: =H28+1 -> 3 | I29: School Upgrades | J29: Always looking to improve quality of the infrastructure of the schools, Professional Development of their staff, evaluation of their staff) | K29: 60 | L29: 15 | M29: =ROUND(L29*K29/60,2) -> 15 | N29: =ROUND(M29*12,0) -> 180
A30: =A29+1 -> 4 | H30: =H29+1 -> 4 | I30: Communication and Public Relations | J30: Online presence | K30: 120 | L30: 4 | M30: =ROUND(L30*K30/60,2) -> 8 | N30: =ROUND(M30*12,0) -> 96
A31: =A30+1 -> 5 | H31: =H30+1 -> 5 | I31: Student Lifecycle | J31: From lead gen to conversion to the end of the year report of student performance | K31: 60 | L31: 24 | M31: =ROUND(L31*K31/60,2) -> 24 | N31: =ROUND(M31*12,0) -> 288
A32: =A31+1 -> 6 | H32: =H31+1 -> 6 | I32: Organisational Wellbeing | J32: General Interactions | K32: 60 | L32: 24 | M32: =ROUND(L32*K32/60,2) -> 24 | N32: =ROUND(M32*12,0) -> 288
A33: =A32+1 -> 7 | H33: =H32+1 -> 7
A34: =A33+1 -> 8 | H34: =H33+1 -> 8
A35: =A34+1 -> 9 | H35: =H34+1 -> 9
A36: =A35+1 -> 10 | H36: =H35+1 -> 10
A37: =A36+1 -> 11 | H37: =H36+1 -> 11
A38: =A37+1 -> 12 | H38: =H37+1 -> 12
A39: =A38+1 -> 13 | H39: =H38+1 -> 13
A40: =A39+1 -> 14 | H40: =H39+1 -> 14
A41: =A40+1 -> 15 | H41: =H40+1 -> 15
A42: =A41+1 -> 16 | H42: =H41+1 -> 16
A43: =A42+1 -> 17 | H43: =H42+1 -> 17
B44: Total | F44: =ROUND(SUM(F27:F43),0) -> 6 | I44: Total | M44: =ROUND(SUM(M27:M43),0) -> 179
...

Sheet EduWand
AC1: < Grouped for outputs
B2: # | C2: Teacher | D2: Workflow Category | E2: Traditional Workflow Description | F2: EduWand Workflow Description | G2: Effciency | H2: Time taken before EduWand in a month | I2: Time taken after EduWand in a month | J2: EduWand with infra | K2: Effciency | L2: Time taken after EduWand + Infra in a month | N2: # | O2: Student | P2: Traditional Workflow Description | Q2: EduWand Workflow Description | R2: Effciency | S2: Time taken before EduWand in a month | T2: Time taken after EduWand in a month | U2: EduWand with infra (Student Hardware is not yet planned) | V2: Effciency | W2: Time taken after EduWand + Infra in a month | AD2: Workflow | AE2: Time without EduWand | AF2: Time with Eduwand | AG2: Efficiency | AH2: % Split without EduWand | AI2: % Split with EduWand
B3: =Traditional!A3 -> 1 | C3: =Traditional!B3 -> Attendance | D3: Administration | E3: =Traditional!C3 -> Daily attendance at the start of the day, recording in registers/ERP system | F3: EduWand helps the teacher record attendance digitally, taking half the time and also tracing it live where the parents are also notifies immedietly to the parents. We also invest and setup biometric scanners to completely take the workflow off the educator for each chapter. | G3: 0.5 | H3: =Traditional!F3 -> 6 | I3: =H3*(1-G3) -> 3 | J3: Bio metric automates everything | K3: 0.9 | L3: =H3*(1-K3) -> 0.6 | N3: =B3 -> 1 | O3: =Traditional!I3 -> Time Spent on AI for education | P3: Students use AI todirectly find answers without putting in the effort to think which is very important for a kids development. However, with NEP pushing learining AI from 3rd grade onwards, it is not rationale to stop students from using AI today | Q3: The student has a Socratic chatbot that they can use to use AI with guardrails in place and the socratic nature engages the students use their thinking | R3: 0 | S3: =Traditional!M3 -> 24 | T3: =IF(R3=0%,S3,R3*S3) -> 24 | U3: NA | V3: NA | W3: NA | AD3: Administration | AE3: =SUMIF($D$3:$D$15,AD3,EduWand!H$3:H$15) -> 59.5 | AF3: =SUMIF($D$3:$D$15,AD3,EduWand!I$3:I$15) -> 30.1 | AG3: =AF3/AE3-1 -> -0.49411765 | AH3: =AE3/$AE$6 -> 0.31746879 | AI3: =AF3/$AF$6 -> 0.22490613
B4: =Traditional!A4 -> 2 | C4: =Traditional!B4 -> Lesson Planning | D4: Class Planning/Grading | E4: =Traditional!C4 -> Each class needs to be planned and teachers keep records or what was done, and what are next classes aimed for and how they can deliver the same (eg: CBSE Mandated 5E lesson plans to be recorded by teachers for documentation) | F4: Lesson Studio helps teachers create learning material in minutes, without the need for promting and app hopping | G4: 0.91666667 | H4: =Traditional!F4 -> 12 | I4: =H4*(1-G4) -> 1 | J4: Dedicated hardware (tablets), enhances speed with local AI | K4: 0.91666667 | L4: =H4*(1-K4) -> 1 | N4: =B4 -> 2 | O4: =Traditional!I4 -> Time Spent in classroom | P4: Daily Classes | Q4: No change in Student classroom behaviour | R4: 0 | S4: =Traditional!M4 -> 108 | T4: =IF(R4=0%,S4,R4*S4) -> 108 | U4: NA | V4: NA | W4: NA | AD4: Class Planning/Grading | AE4: =SUMIF($D$3:$D$15,AD4,EduWand!H$3:H$15) -> 29.67 | AF4: =SUMIF($D$3:$D$15,AD4,EduWand!I$3:I$15) -> 7.4836111 | AG4: =AF4/AE4-1 -> -0.74777179 | AH4: =AE4/$AE$6 -> 0.15830754 | AI4: =AF4/$AF$6 -> 0.055917277
B5: =Traditional!A5 -> 3 | C5: =Traditional!B5 -> Question Bank | D5: Class Planning/Grading | E5: =Traditional!C5 -> Currently only happens for quarter end exams, sources include external guides, competitive exam books, school purchased Books (all static material, nothing adjusting to the need and understanding of a kid) | F5: Assignment Lab helps educators create and grade personalised assignments for each kid in the class. For example, in a class of 30 students, based on the their historical performance, 40% of the assignment is customised for the kid. All of the data is analytically shown to the teacher at all times; LIVE! | G5: 0.97222222 | H5: =Traditional!F5 -> 1 | I5: =H5*(1-G5) -> 0.027777778 | J5: Dedicated hardware (tablets), enhances speed with local AI | K5: 0.98194444 | L5: =H5*(1-K5) -> 0.018055556 | N5: =B5 -> 3 | O5: =Traditional!I5 -> Homework (if any:P) | P5: Homework from daily lectures | Q5: Daily/weekly personalised assignments shared by the teacher on the application | R5: 0.2 | S5: =Traditional!M5 -> 12 | T5: =IF(R5=0%,S5,R5*S5) -> 2.4 | U5: NA | V5: NA | W5: NA | AD5: Teaching | AE5: =SUMIF($D$3:$D$15,AD5,EduWand!H$3:H$15) -> 98.25 | AF5: =SUMIF($D$3:$D$15,AD5,EduWand!I$3:I$15) -> 96.25 | AG5: =AF5/AE5-1 -> -0.020356234 | AH5: =AE5/$AE$6 -> 0.52422367 | AI5: =AF5/$AF$6 -> 0.71917659
B6: =Traditional!A6 -> 4 | C6: =Traditional!B6 -> Content Research | D6: Class Planning/Grading | E6: =Traditional!C6 -> This would include the teacher trying to find online material from youtube, google to explain the same topics in the books available | F6: Lesson Studio helps teachers create reseach reports in minutes, without the need for promting and app hopping | G6: 0.91666667 | H6: =Traditional!F6 -> 0.67 | I6: =H6*(1-G6) -> 0.055833333 | J6: Dedicated hardware (tablets), enhances speed with local AI | K6: 0.91666667 | L6: =H6*(1-K6) -> 0.055833333 | N6: =B6 -> 4 | O6: =Traditional!I6 -> Co-curricular activities (Projects,competitions etc) | P6: Open Internet search | Q6: Can use the AI socratic chatbot for the project | R6: 0.2 | S6: =Traditional!M6 -> 12 | T6: =IF(R6=0%,S6,R6*S6) -> 2.4 | U6: NA | V6: NA | W6: NA | AD6: Total | AE6: =SUM(AE3:AE5) -> 187.42 | AF6: =SUM(AF3:AF5) -> 133.83361 | AG6: =AF6/AE6-1 -> -0.28591606 | AH6: =AE6/$AE$6 -> 1 | AI6: =AF6/$AF$6 -> 1
B7: =Traditional!A7 -> 5 | C7: =Traditional!B7 -> Doubt Solving | D7: Teaching | E7: =Traditional!C7 -> Happens immedietly whena students gets a chance to talk to the teacher, if this happens often after a class, takes up an entire lecture. | F7: The Socratic chatbot helps the student; not by giving them the answer directly but guide them towards the answers, after a few tries, the student has the option to reach out to the teacher, and the teacher can answer the question | G7: 0.88888889 | H7: =Traditional!F7 -> 2.25 | I7: =H7*(1-G7) -> 0.25 | J7: Dedicated hardware (tablets), enhances speed with local AI | K7: 0.91555556 | L7: =H7*(1-K7) -> 0.19 | N7: =B7 -> 5
B8: =Traditional!A8 -> 6 | C8: =Traditional!B8 -> Parent Communication | D8: Administration | E8: =Traditional!C8 -> In some schools parents are updated on a daily basis of what was done in class through Whatsapp. Rarely any school has a central app for communication. A teacher with a class of 25 students has to deal with 25 set of parents at a time, with updates on groups and responding to individual doubts. | F8: The application gives a parent login where they can track live what is going on in their kid's classroom, with a direct chat with the teacher (teacher is notified and can get back to them at the earliest). | G8: 0.5 | H8: =Traditional!F8 -> 12 | I8: =H8*(1-G8) -> 6 | J8: No Upgrades | K8: 0.5 | L8: =H8*(1-K8) -> 6 | N8: =B8 -> 6
B9: =Traditional!A9 -> 7 | C9: =Traditional!B9 -> Notebook Correction (Homework) | D9: Class Planning/Grading | E9: =Traditional!C9 -> Teachers get their students to do daily assignments in notebooks (K-12), which if the teacher has time, carries it back and forth from classrom to home to staff room to classroom, exposing risks to injury. | F9: Assignments are first graded by AI highlighting how the student performed, and what are the suggested next steps for the student to improve on, shortining the feedback loop and highlighting severe cases which go unidentified in traditional methods | G9: 0.6 | H9: =Traditional!F9 -> 16 | I9: =H9*(1-G9) -> 6.4 | J9: Dedicated hardware (tablets), enhances speed with local AI | K9: 0.7 | L9: =H9*(1-K9) -> 4.8 | N9: =B9 -> 7
B10: =Traditional!A10 -> 8 | C10: =Traditional!B10 -> LMS Update | D10: Administration | E10: =Traditional!C10 -> Any Learning material the teacher used in class is updated on an LMS Portal (which is never looked back on) | F10: Any learning material created or used from the content library, is automatically linked in the classroom database. This is accesible to the parents and students for the entire academic year. | G10: 1 | H10: =Traditional!F10 -> 4 | I10: =H10*(1-G10) -> 0 | J10: No Upgrades | K10: 1 | L10: =H10*(1-K10) -> 0 | N10: =B10 -> 8
B11: =Traditional!A11 -> 9 | C11: =Traditional!B11 -> Teaching | D11: Teaching | E11: =Traditional!C11 -> A K12 Teacher has 3-4 lectures per day | F11: Teaching hours are unchanged. Automation lets the teacher structure the class better — cover more syllabus or spend longer on the same topic — but the hours themselves are not reclaimed and are excluded from the time-saving claim. | G11: 0 | H11: =Traditional!F11 -> 96 | I11: =H11*(1-G11) -> 96 | J11: Dedicated hardware (tablets), enhances speed with local AI | K11: 0 | L11: =H11*(1-K11) -> 96 | N11: =B11 -> 9
B12: =Traditional!A12 -> 10 | C12: =Traditional!B12 -> Assembly | D12: Administration | E12: =Traditional!C12 -> Every school holds an assembly everyday. Planning involves - news runs, thought of the day, pledge, notice announcments, awards, birthdays. | F12: Custom AI automation project layer enables the institute to automate SOP ased task with human in the loop mechanism | G12: 0.8 | H12: =Traditional!F12 -> 1 | I12: =H12*(1-G12) -> 0.2 | J12: Dedicated hardware (tablets), enhances speed with local AI | K12: 0.82 | L12: =H12*(1-K12) -> 0.18 | N12: =B12 -> 10
B13: =Traditional!A13 -> 11 | C13: =Traditional!B13 -> Report Building | D13: Administration | E13: =Traditional!C13 -> Ad hoc reports of students/class/incedent for internal meetings | F13: Custom Live Analytical dashoard with the ERP Layer to look at the entire class data or a single student at any given time | G13: 0.8 | H13: =Traditional!F13 -> 2.5 | I13: =H13*(1-G13) -> 0.5 | J13: Dedicated hardware (tablets), enhances speed with local AI | K13: 0.82 | L13: =H13*(1-K13) -> 0.45 | N13: =B13 -> 11
B14: =Traditional!A14 -> 12 | C14: =Traditional!B14 -> Co Corricular Activities | D14: Administration | E14: =Traditional!C14 -> Planning and conducting events/activities/picnics etc to keep students engaged | F14: The lessonstudio can help the teachers make event plans and reports without the need for prompting and app hoping | G14: 0.4 | H14: =Traditional!F14 -> 4 | I14: =H14*(1-G14) -> 2.4 | J14: No Upgrades | K14: 0.4 | L14: =H14*(1-K14) -> 2.4 | N14: =B14 -> 12
B15: =Traditional!A15 -> 13 | C15: =Traditional!B15 -> School Events | D15: Administration | E15: =Traditional!C15 -> Annual Event Planning - Assumption includes the amount spent on practice in that one month of prepping towards the events | F15: The lessonstudio can help the teachers make event plans and reports without the need for prompting and app hoping | G15: 0.4 | H15: =Traditional!F15 -> 30 | I15: =H15*(1-G15) -> 18 | J15: No Upgrades | K15: 0.4 | L15: =H15*(1-K15) -> 18 | N15: =B15 -> 13
B16: =Traditional!A16 -> 14 | C16: =Traditional!B16 -> 0 | E16: =Traditional!C16 -> 0 | F16: . | L16: =Traditional!D16 -> 0
B17: =Traditional!A17 -> 15 | C17: =Traditional!B17 -> 0 | E17: =Traditional!C17 -> 0 | L17: =Traditional!D17 -> 0
F18: Total | H18: =SUM(H3:H15) -> 187.42 | I18: =SUM(I3:I15) -> 133.83361 | L18: =SUM(L3:L15) -> 129.69389 | Q18: Total | S18: =SUM(S3:S15) -> 156 | T18: =SUM(T3:T15) -> 136.8 | W18: =SUM(W3:W15) -> 0
F19: Weekly Average | H19: =H18/4 -> 46.855 | I19: =I18/4 -> 33.458403 | L19: =L18/4 -> 32.423472 | Q19: Weekly Average | S19: =S18/4 -> 39 | T19: =T18/4 -> 34.2 | W19: =W18/4 -> 0
F20: Daily Average | H20: =H19/6 -> 7.8091667 | I20: =I19/6 -> 5.5764005 | L20: =L19/6 -> 5.403912 | Q20: Daily Average | S20: =S19/6 -> 6.5 | T20: =T19/6 -> 5.7 | W20: =W19/6 -> 0
F21: Time Saved | I21: =1-I18/H18 -> 0.28591606 | L21: =1-L18/H18 -> 0.30800401 | Q21: Time Saved | T21: =T18/S18-1 -> -0.12307692
F22: Time saved (hrs / teacher / month) | I22: =H18-I18 -> 53.586389 | L22: =H18-L18 -> 57.726111
F23: of which administrative workflows (excl. Teaching & Doubt Solving) | I23: =(H18-H11-H7)-(I18-I11-I7) -> 51.586389 | L23: =(H18-H11-H7)-(L18-L11-L7) -> 55.666111
B25: # | C25: Parent | D25: Workflow Category | E25: Traditional Workflow Description | F25: EduWand Workflow Description | G25: Effciency | H25: Time taken before EduWand in a month | I25: Time taken after EduWand in a month | J25: EduWand with infra | K25: Effciency | L25: Time taken after EduWand + Infra in a month | N25: # | O25: Administrator | P25: Traditional Workflow Description | Q25: EduWand Workflow Description | R25: Effciency | S25: Time taken before EduWand in a month | T25: Time taken after EduWand in a month | U25: EduWand with infra | V25: Effciency | W25: Time taken after EduWand + Infra in a month
B26: =B3 -> 1 | C26: =Traditional!B27 -> Teacher Interaction | D26: Communication | E26: Check ins with teacher, getting updates on their child etc | F26: One app for centralised communication | G26: 0.3 | H26: =Traditional!F27 -> 2.5 | I26: =H26*(1-G26) -> 1.75 | J26: NA | K26: NA | L26: NA | N26: =B26 -> 1 | O26: =Traditional!I27 -> Vendor Management | P26: =Traditional!J27 -> Approving bills, co ordinating contracts, Budgeting and Buying | Q26: One cental dashboard to manage any vendor interaction | R26: 0.4 | S26: =Traditional!M27 -> 48 | T26: =S26*(1-R26) -> 28.8 | U26: NA | V26: NA | W26: NA
B27: =B26+1 -> 2 | C27: =Traditional!B28 -> Child Interaction | D27: Parent Involvement | E27: Sit with their children to help them with homework | F27: similary leveraged with the socratic chatbot | G27: 0.2 | H27: =Traditional!F28 -> 2.5 | I27: =H27*(1-G27) -> 2 | J27: NA | K27: NA | L27: NA | N27: =N26+1 -> 2 | O27: =Traditional!I28 -> School Organization and Staffing | P27: =Traditional!J28 -> Staffing teachers and managing their schedule, Leadership and Culture, Programming and building systems, Hiring and training | Q27: Data analytics with agentic AI layer, helps the adminnistrator staff their educators efficiently | R27: 0.4 | S27: =Traditional!M28 -> 60 | T27: =S27*(1-R27) -> 36 | U27: NA | V27: NA | W27: NA
B28: =B27+1 -> 3 | C28: =Traditional!B29 -> Administrative activities | D28: Administrative | E28: Admissions, PTM, Payments | F28: One app for centralised student life cycle | G28: 0.5 | H28: =Traditional!F29 -> 0.67 | I28: =H28*(1-G28) -> 0.335 | J28: NA | K28: NA | L28: NA | N28: =N27+1 -> 3 | O28: =Traditional!I29 -> School Upgrades | P28: =Traditional!J29 -> Always looking to improve quality of the infrastructure of the schools, Professional Development of their staff, evaluation of their staff) | Q28: We connect CPD program 3rd parties with institutions to provide training to their staff | R28: 0.2 | S28: =Traditional!M29 -> 15 | T28: =S28*(1-R28) -> 12 | U28: NA | V28: NA | W28: NA
B29: =B28+1 -> 4 | N29: =N28+1 -> 4 | O29: =Traditional!I30 -> Communication and Public Relations | P29: =Traditional!J30 -> Online presence | Q29: Central app for pushing notices to all stakeholders | R29: 0.2 | S29: =Traditional!M30 -> 8 | T29: =S29*(1-R29) -> 6.4 | U29: NA | V29: NA | W29: NA
B30: =B29+1 -> 5 | N30: =N29+1 -> 5 | O30: =Traditional!I31 -> Student Lifecycle | P30: =Traditional!J31 -> From lead gen to conversion to the end of the year report of student performance | Q30: Everything is tracked from the first conversation to outbout messages to convert the lead and the entire student lifecycle digitally | R30: 0.3 | S30: =Traditional!M31 -> 24 | T30: =S30*(1-R30) -> 16.8 | U30: NA | V30: NA | W30: NA
B31: =B30+1 -> 6 | N31: =N30+1 -> 6 | O31: =Traditional!I32 -> Organisational Wellbeing | P31: =Traditional!J32 -> General Interactions | Q31: Similar workflow | R31: 0 | S31: =Traditional!M32 -> 24 | T31: =S31*(1-R31) -> 24 | U31: NA | V31: NA | W31: NA
B32: =B31+1 -> 7 | N32: =N31+1 -> 7
B33: =B32+1 -> 8 | N33: =N32+1 -> 8
B34: =B33+1 -> 9 | N34: =N33+1 -> 9
B35: =B34+1 -> 10 | N35: =N34+1 -> 10
B36: =B35+1 -> 11 | N36: =N35+1 -> 11
B37: =B36+1 -> 12 | N37: =N36+1 -> 12
B38: =B37+1 -> 13 | N38: =N37+1 -> 13
B39: =B38+1 -> 14 | N39: =N38+1 -> 14
B40: =B39+1 -> 15 | N40: =N39+1 -> 15
F41: Total | H41: =SUM(H26:H38) -> 5.67 | I41: =SUM(I26:I38) -> 4.085 | L41: =SUM(L26:L38) -> 0 | Q41: Total | S41: =SUM(S26:S38) -> 179 | T41: =SUM(T26:T38) -> 124 | W41: =SUM(W26:W38) -> 0
...
